Workbook

Sheet Topsheet
A1: Variable labor KPI sheet
A5: Hours - total | C5: 25.01 | D5: 25.02 | E5: 25.03 | F5: 25.04 | G5: 25.05 | H5: 25.06 | I5: 25.07 | J5: 25.08 | K5: 25.09 | L5: 25.10 | M5: 25.11 | N5: 25.12
A6: Hours own personnel | B6: Budget | C6: 13969.53 | D6: 12726.131 | E6: 13347.83 | F6: 13093.904 | G6: 12472.205 | H6: 12726.131 | I6: 11925.002 | J6: 10681.603 | K6: 13969.53 | L6: 14591.229 | M6: 12726.131 | N6: 12586.051
A7: Hours temp personnel | B7: Budget | C7: 19259.637 | D7: 20503.035 | E7: 19881.336 | F7: 17752.939 | G7: 18378.768 | H7: 18118.271 | I7: 19020.801 | J7: 20272.969 | K7: 16911.671 | L7: 16285.309 | M7: 18164.341 | N7: 18364.948
B8: Budget | C8: =C7+C6 -> 33229.167 | D8: =D7+D6 -> 33229.167 | E8: =E7+E6 -> 33229.167 | F8: =F7+F6 -> 30846.843 | G8: =G7+G6 -> 30850.973 | H8: =H7+H6 -> 30844.402 | I8: =I7+I6 -> 30945.802 | J8: =J7+J6 -> 30954.572 | ... N8: =N7+N6 -> 30951
A9: Hours converted to FTE | B9: Budget | C9: =C8/C36/8 -> 188.80208 | D9: =D8/D36/8 -> 207.68229 | E9: =E8/E36/8 -> 197.79266 | F9: =F8/F36/8 -> 183.61216 | G9: =G8/G36/8 -> 192.81858 | H9: =H8/H36/8 -> 192.77751 | I9: =I8/I36/8 -> 168.18371 | J9: =J8/J36/8 -> 184.2534 | ... N9: =N8/N36/8 -> 184.23214
A11: Hours own personnel | B11: Actual | C11: =33360-C12 -> 13292 | D11: =11199-1258+627 -> 10568 | E11: =32241-E12 -> 10931 | F11: =28902-F12 -> 11081 | G11: =26620-G12 -> 9589 | H11: =27296-H12 -> 10172 | I11: =30239-I12 -> 11692 | J11: =26792-J12 -> 9468 | K11: =26456-K12 -> 9351 | L11: =28443-L12 -> 10281 | M11: =24871-M12 -> 10000
A12: Hours temp personnel | B12: Actual | C12: 20068 | D12: =19645+630 -> 20275 | E12: 21310 | F12: 17821 | G12: 17031 | H12: 17124 | I12: 18547 | J12: 17324 | K12: 17105 | L12: 18162 | M12: 14871
B13: Actual | C13: =C12+C11 -> 33360 | D13: =D12+D11 -> 30843 | E13: =E12+E11 -> 32241 | F13: =F12+F11 -> 28902 | G13: =G12+G11 -> 26620 | H13: =H12+H11 -> 27296 | I13: =I12+I11 -> 30239 | J13: =J12+J11 -> 26792 | ... N13: =N12+N11 -> 0
A14: Hours converted to FTE | B14: Actual | C14: =C13/C36/8 -> 189.54545 | D14: =D13/D36/8 -> 192.76875 | E14: =E13/E36/8 -> 191.91071 | F14: =F13/F36/8 -> 172.03571 | G14: =G13/G36/8 -> 166.375 | H14: =H13/H36/8 -> 170.6 | I14: =I13/I36/8 -> 164.34239 | J14: =J13/J36/8 -> 159.47619 | ... N14: =N13/N36/8 -> 0
A17: Delta Budget vs Actual | B17: Hours | C17: =C13-C8 -> 130.83333 | D17: =D13-D8 -> -2386.1667 | E17: =E13-E8 -> -988.16667 | F17: =F13-F8 -> -1944.8435 | G17: =G13-G8 -> -4230.9726 | H17: =H13-H8 -> -3548.4023 | I17: =I13-I8 -> -706.80249 | J17: =J13-J8 -> -4162.5719 | ... M17: =M13-M8 -> -6019.4725
A18: Delta Budget vs Actual | B18: FTE | C18: =C14-C9 -> 0.74337121 | D18: =D14-D9 -> -14.913542 | E18: =E14-E9 -> -5.8819444 | F18: =F14-F9 -> -11.576449 | G18: =G14-G9 -> -26.443579 | H18: =H14-H9 -> -22.177515 | I18: =I14-I9 -> -3.8413179 | J18: =J14-J9 -> -24.777214 | ... M18: =M14-M9 -> -37.621703
A21: Sickrate | C21: 25.01 | D21: 25.02 | E21: 25.03 | F21: 25.04 | G21: 25.05 | H21: 25.06 | I21: 25.07 | J21: 25.08 | K21: 25.09 | L21: 25.10 | M21: 25.11 | N21: 25.12
A22: Sickrate blue collars | B22: Budget | C22: 0.05 | D22: 0.05 | E22: 0.05 | F22: 0.05 | G22: 0.05 | H22: 0.05 | I22: 0.05 | J22: 0.05 | K22: 0.05 | L22: 0.05 | M22: 0.05 | N22: 0.05
A23: Sickrate blue collars | B23: Actual | C23: 0.053 | D23: 0.075 | E23: 0.025 | F23: 0.037 | G23: 0.039 | H23: 0.054 | I23: 0.0337 | J23: 0.04 | K23: 0.0679 | L23: 0.1194 | M23: 0.1019
A26: Costs | C26: 25.01 | D26: 25.02 | E26: 25.03 | F26: 25.04 | G26: 25.05 | H26: 25.06 | I26: 25.07 | J26: 25.08 | K26: 25.09 | L26: 25.10 | M26: 25.11 | N26: 25.12
A27: Costs - total | B27: Budget | C27: 965924.92 | D27: 969119.79 | E27: 967522.36 | F27: 900615.79 | G27: 902213.22 | H27: 899673.96 | I27: 940490.45 | J27: 944191.36 | K27: 914078.9 | L27: 912228.44 | M27: 917779.81 | N27: 942680.31
A28: Costs - total | B28: Actual | C28: 985015 | D28: =885317 -> 885317 | E28: 936597 | F28: 844696.75 | G28: 791847.81 | H28: 817799.87 | I28: 931475.59 | J28: 829022.92 | K28: 816500.17 | L28: 885831.76 | M28: 769079.78
B29: Delta | C29: =C28-C27 -> 19090.083 | D29: =D28-D27 -> -83802.794 | E29: =E28-E27 -> -30925.356 | F29: =F28-F27 -> -55919.036 | G29: =G28-G27 -> -110365.41 | H29: =H28-H27 -> -81874.091 | I29: =I28-I27 -> -9014.858 | J29: =J28-J27 -> -115168.44 | ... M29: =M28-M27 -> -148700.03
A30: Costs / worked hour | C30: =(C28/C13) -> 29.526829 | D30: =(D28/D13) -> 28.703985 | E30: =(E28/E13) -> 29.049874 | F30: =(F28/F13) -> 29.226239 | G30: =(G28/G13) -> 29.746349 | H30: =(H28/H13) -> 29.960429 | I30: =(I28/I13) -> 30.803783 | J30: =(J28/J13) -> 30.942928 | ... M30: =(M28/M13) -> 30.922753
A32: Idle hours | B32: Hours | C32: 443 | D32: 102 | E32: 395 | F32: 387 | G32: 293.7 | H32: 233.46 | I32: 381.48 | J32: 336.55 | K32: 473.04 | L32: 363.5 | M32: 624.85
A33: Idle hours | B33: Costs | C33: =C32*C30 -> 13080.385 | D33: =D32*D30 -> 2927.8064 | E33: =E32*E30 -> 11474.7 | F33: =F32*F30 -> 11310.554 | G33: =G32*G30 -> 8736.5027 | H33: =H32*H30 -> 6994.5618 | I33: =I32*I30 -> 11751.027 | J33: =J32*J30 -> 10413.842 | ... M33: =M32*M30 -> 19322.082
A36: Workdays per month | B36: 2025 | C36: 22 | D36: 20 | E36: 21 | F36: 21 | G36: 20 | H36: 20 | I36: 23 | J36: 21 | K36: 22 | L36: 23 | M36: 20 | N36: 21
A37: Explanation delta costs / worked hour
A38: Costs impact sick leave vs budget | B38: Total | C38: =(C23-C22)*C6*C30 -> 1237.4277 | D38: =(D23-D22)*D6*D30 -> 9132.2669 | E38: =(E23-E22)*E6*E30 -> -9693.8199 | F38: =(F23-F22)*F6*F30 -> -4974.9123 | G38: =(G23-G22)*G6*G30 -> -4081.0281 | H38: =(H23-H22)*H6*H30 -> 1525.1214 | I38: =(I23-I22)*I6*I30 -> -5987.5631 | J38: =(J23-J22)*J6*J30 -> -3305.2008 | ... M38: =(M23-M22)*M6*M30 -> 20424.052
A39: Costs impact Temp agency costs increase | B39: Total | C39: 12102 | D39: 0 | E39: 0 | F39: 0 | G39: =-C39 -> -12102 | H39: =-D39 -> 0 | I39: =-E39 -> 0 | J39: =-F39 -> 0 | K39: =-G39 -> 12102 | M39: 0
A42: Admin staff
A43: FTE admin staff | B43: Budget | C43: 28.7 | D43: 28.7 | E43: 28.7 | F43: 28.7 | G43: 28.7 | H43: 28.7 | I43: 28.7 | J43: 28.7 | K43: 28.7 | L43: 28.7 | M43: 28.7 | N43: 28.7
A44: FTE admin staff | B44: Actual | C44: 26.7 | D44: 38.4 | E44: 41.4 | F44: 42.275 | G44: 42.275 | H44: 41.075 | I44: 41.075 | J44: 39.075 | K44: 39.075 | L44: 38.075 | M44: 38.075
B45: Delta | C45: =C44-C43 -> -2 | D45: =D44-D43 -> 9.7 | E45: =E44-E43 -> 12.7 | F45: =F44-F43 -> 13.575 | G45: =G44-G43 -> 13.575 | H45: =H44-H43 -> 12.375 | I45: =I44-I43 -> 12.375 | J45: =J44-J43 -> 10.375 | ... M45: =M44-M43 -> 9.375
A47: Total FTEs | B47: Budget | C47: =C43+C9 -> 217.50208 | D47: =D43+D9 -> 236.38229 | E47: =E43+E9 -> 226.49266 | F47: =F43+F9 -> 212.31216 | G47: =G43+G9 -> 221.51858 | H47: =H43+H9 -> 221.47751 | I47: =I43+I9 -> 196.88371 | J47: =J43+J9 -> 212.9534 | ... M47: =M43+M9 -> 221.76545
A48: Total FTEs | B48: Actual | C48: =C14+C44 -> 216.24545 | D48: =D14+D44 -> 231.16875 | E48: =E14+E44 -> 233.31071 | F48: =F14+F44 -> 214.31071 | G48: =G14+G44 -> 208.65 | H48: =H14+H44 -> 211.675 | I48: =I14+I44 -> 205.41739 | J48: =J14+J44 -> 198.55119 | ... M48: =M14+M44 -> 193.51875
A49: Total FTEs | B49: Delta | C49: =C48-C47 -> -1.2566288 | D49: =D48-D47 -> -5.2135417 | E49: =E48-E47 -> 6.8180556 | F49: =F48-F47 -> 1.9985506 | G49: =G48-G47 -> -12.868579 | H49: =H48-H47 -> -9.8025145 | I49: =I48-I47 -> 8.5336821 | J49: =J48-J47 -> -14.402214 | ... M49: =M48-M47 -> -28.246703

Sheet Hours & volumes per subgroup
A1: Hours | C1: 25.01 | D1: 25.02 | E1: 25.03 | F1: 25.04 | G1: 25.05 | H1: 25.06 | I1: 25.07 | J1: 25.08 | K1: 25.09 | L1: 25.10 | M1: 25.11 | N1: 25.12
A2: R&P | B2: Budget | C2: 3548.1143 | D2: 3548.1143 | E2: 3548.1143 | F2: 3548.1143 | G2: 3548.1143 | H2: 3548.1143 | I2: 3544.6249 | J2: 3544.6249 | K2: 3544.6249 | L2: 3544.6249 | M2: 3544.6249 | N2: 3541.2039 | Q2: Extra explanation
A3: R&P | B3: Actual | C3: 3645 | D3: 4215 | E3: 4785 | F3: 4503 | G3: 4646.3333 | H3: 4428.45 | I3: 5053.35 | J3: 4668.0667 | K3: 4500.35 | L3: 5099.6 | M3: 4376.1667 | Q3: Hours idle time fall within the specific group
A4: R&P | B4: Delta | C4: =C3-C2 -> 96.885668 | D4: =D3-D2 -> 666.88567 | E4: =E3-E2 -> 1236.8857 | F4: =F3-F2 -> 954.88567 | G4: =G3-G2 -> 1098.219 | H4: =H3-H2 -> 880.33567 | I4: =I3-I2 -> 1508.7251 | J4: =J3-J2 -> 1123.4418 | ... N4: =N3-N2 -> -3541.2039 | Q4: Hours 'Other' is mainly supervision & cleaning
A6: VAL | B6: Budget | C6: 6505.7103 | D6: 6505.7103 | E6: 6505.7103 | F6: 6505.7103 | G6: 6505.7103 | H6: 6505.7103 | I6: 6499.3122 | J6: 6499.3122 | K6: 6499.3122 | L6: 6499.3122 | M6: 6499.3122 | N6: 6493.0395
A7: VAL | B7: Actual | C7: 6034 | D7: 5875 | E7: 6341 | F7: 6515 | G7: 5906 | H7: 6375.6833 | I7: 6665.6333 | J7: 6269.0833 | K7: 5680.1167 | L7: 6511.8 | M7: 5383.5167
A8: VAL | B8: Delta | C8: =C7-C6 -> -471.71034 | D8: =D7-D6 -> -630.71034 | E8: =E7-E6 -> -164.71034 | F8: =F7-F6 -> 9.2896586 | G8: =G7-G6 -> -599.71034 | H8: =H7-H6 -> -130.02701 | I8: =I7-I6 -> 166.32113 | J8: =J7-J6 -> -230.22887 | ... N8: =N7-N6 -> -6493.0395
A10: FG | B10: Budget | C10: 20873.321 | D10: 20873.321 | E10: 20873.321 | F10: 18491.321 | G10: 18495.321 | H10: 18488.321 | I10: 18601.793 | J10: 18610.793 | K10: 18537.793 | L10: 18532.793 | M10: 18546.793 | N10: 18619.268
A11: FG | B11: Actual | C11: =22700-151 -> 22549 | D11: =-13+19516 -> 19503 | E11: =19077+1023 -> 20100 | F11: 16940 | G11: 15226.833 | H11: 15478.817 | I11: 17710.183 | J11: 15123.233 | K11: 15336.297 | L11: 15865.367 | M11: 14199.28
A12: FG | B12: Delta | C12: =C11-C10 -> 1675.6786 | D12: =D11-D10 -> -1370.3214 | E12: =E11-E10 -> -773.32141 | F12: =F11-F10 -> -1551.3214 | G12: =G11-G10 -> -3268.4881 | H12: =H11-H10 -> -3009.5047 | I12: =I11-I10 -> -891.60989 | J12: =J11-J10 -> -3487.5599 | ... N12: =N11-N10 -> -18619.268
A14: Other | B14: Budget | C14: 2302.0206 | D14: 2302.0206 | E14: 2302.0206 | F14: 2302.0206 | G14: 2302.0206 | H14: 2302.0206 | I14: 2299.7566 | J14: 2299.7566 | K14: 2299.7566 | L14: 2299.7566 | M14: 2299.7566 | N14: 2297.5371
A15: Other | B15: Actual | C15: 1132 | D15: 1250 | E15: 1016 | F15: 943 | G15: 840 | H15: 1013.05 | I15: 809.83333 | J15: 916.1 | K15: 962.27 | L15: 1031.7 | M15: 913.36667
A16: Other | B16: Delta | C16: =C15-C14 -> -1170.0206 | D16: =D15-D14 -> -1052.0206 | E16: =E15-E14 -> -1286.0206 | F16: =F15-F14 -> -1359.0206 | G16: =G15-G14 -> -1462.0206 | H16: =H15-H14 -> -1288.9706 | I16: =I15-I14 -> -1489.9233 | J16: =J15-J14 -> -1383.6566 | ... N16: =N15-N14 -> -2297.5371
A19: FTE | C19: 25.01 | D19: 25.02 | E19: 25.03 | F19: 25.04 | G19: 25.05 | H19: 25.06 | I19: 25.07 | J19: 25.08 | K19: 25.09 | L19: 25.10 | M19: 25.11 | N19: 25.12
A20: R&P | B20: Budget | C20: =C2/8/C37 -> 20.159741 | D20: =D2/8/D37 -> 22.175715 | E20: =E2/8/E37 -> 21.119728 | F20: =F2/8/F37 -> 21.119728 | G20: =G2/8/G37 -> 22.175715 | H20: =H2/8/H37 -> 22.175715 | I20: =I2/8/I37 -> 19.264266 | J20: =J2/8/J37 -> 21.098958 | ... N20: =N2/8/N37 -> 21.078594
A21: R&P | B21: Actual | C21: =C3/8/C37 -> 20.710227 | D21: =D3/8/D37 -> 26.34375 | E21: =E3/8/E37 -> 28.482143 | F21: =F3/8/F37 -> 26.803571 | G21: =G3/8/G37 -> 29.039583 | H21: =H3/8/H37 -> 27.677813 | I21: =I3/8/I37 -> 27.463859 | J21: =J3/8/J37 -> 27.786111 | ... N21: =N3/8/N37 -> 0
A22: R&P | B22: Delta | C22: =C21-C20 -> 0.55048675 | D22: =D21-D20 -> 4.1680354 | E22: =E21-E20 -> 7.3624147 | F22: =F21-F20 -> 5.6838433 | G22: =G21-G20 -> 6.8638688 | H22: =H21-H20 -> 5.5020979 | I22: =I21-I20 -> 8.199593 | J22: =J21-J20 -> 6.6871535 | ... N22: =N21-N20 -> -21.078594
A24: VAL | B24: Budget | C24: =C6/8/C37 -> 36.964263 | D24: =D6/8/D37 -> 40.66069 | E24: =E6/8/E37 -> 38.724466 | F24: =F6/8/F37 -> 38.724466 | G24: =G6/8/G37 -> 40.66069 | H24: =H6/8/H37 -> 40.66069 | I24: =I6/8/I37 -> 35.322349 | J24: =J6/8/J37 -> 38.686382 | ... N24: =N6/8/N37 -> 38.649045
A25: VAL | B25: Actual | C25: =C7/8/C37 -> 34.284091 | D25: =D7/8/D37 -> 36.71875 | E25: =E7/8/E37 -> 37.744048 | F25: =F7/8/F37 -> 38.779762 | G25: =G7/8/G37 -> 36.9125 | H25: =H7/8/H37 -> 39.848021 | I25: =I7/8/I37 -> 36.226268 | J25: =J7/8/J37 -> 37.315972 | ... N25: =N7/8/N37 -> 0
A26: VAL | B26: Delta | C26: =C25-C24 -> -2.6801724 | D26: =D25-D24 -> -3.9419396 | E26: =E25-E24 -> -0.9804187 | F26: =F25-F24 -> 0.055295587 | G26: =G25-G24 -> -3.7481896 | H26: =H25-H24 -> -0.8126688 | I26: =I25-I24 -> 0.9039192 | J26: =J25-J24 -> -1.3704099 | ... N26: =N25-N24 -> -38.649045
A28: FG | B28: Budget | C28: =C10/8/C37 -> 118.59842 | D28: =D10/8/D37 -> 130.45826 | E28: =E10/8/E37 -> 124.24596 | F28: =F10/8/F37 -> 110.06739 | G28: =G10/8/G37 -> 115.59576 | H28: =H10/8/H37 -> 115.55201 | I28: =I10/8/I37 -> 101.0967 | J28: =J10/8/J37 -> 110.77853 | ... N28: =N10/8/N37 -> 110.82897
A29: FG | B29: Actual | C29: =C11/8/C37 -> 128.11932 | D29: =D11/8/D37 -> 121.89375 | E29: =E11/8/E37 -> 119.64286 | F29: =F11/8/F37 -> 100.83333 | G29: =G11/8/G37 -> 95.167708 | H29: =H11/8/H37 -> 96.742604 | I29: =I11/8/I37 -> 96.250996 | J29: =J11/8/J37 -> 90.019246 | ... N29: =N11/8/N37 -> 0
A30: FG | B30: Delta | C30: =C29-C28 -> 9.5209011 | D30: =D29-D28 -> -8.5645088 | E30: =E29-E28 -> -4.6031036 | F30: =F29-F28 -> -9.234056 | G30: =G29-G28 -> -20.42805 | H30: =H29-H28 -> -18.809405 | I30: =I29-I28 -> -4.8457059 | J30: =J29-J28 -> -20.759285 | ... N30: =N29-N28 -> -110.82897
A32: Other | B32: Budget | C32: =C14/C37/8 -> 13.079662 | D32: =D14/D37/8 -> 14.387629 | E32: =E14/E37/8 -> 13.702503 | F32: =F14/F37/8 -> 13.702503 | G32: =G14/G37/8 -> 14.387629 | H32: =H14/H37/8 -> 14.387629 | I32: =I14/I37/8 -> 12.498677 | J32: =J14/J37/8 -> 13.689028 | ... N32: =N14/N37/8 -> 13.675816
A33: Other | B33: Actual | C33: =C15/8/C37 -> 6.4318182 | D33: =D15/8/D37 -> 7.8125 | E33: =E15/8/E37 -> 6.047619 | F33: =F15/8/F37 -> 5.6130952 | G33: =G15/8/G37 -> 5.25 | H33: =H15/8/H37 -> 6.3315625 | I33: =I15/8/I37 -> 4.4012681 | J33: =J15/8/J37 -> 5.4529762 | ... N33: =N15/8/N37 -> 0
A34: Other | B34: Delta | C34: =C33-C32 -> -6.6478442 | D34: =D33-D32 -> -6.5751286 | E34: =E33-E32 -> -7.6548844 | F34: =F33-F32 -> -8.0894082 | G34: =G33-G32 -> -9.1376286 | H34: =H33-H32 -> -8.0560661 | I34: =I33-I32 -> -8.0974092 | J34: =J33-J32 -> -8.2360513 | ... N34: =N33-N32 -> -13.675816
A36: Volumes | C36: 25.01 | D36: 25.02 | E36: 25.03 | F36: 25.04 | G36: 25.05 | H36: 25.06 | I36: 25.07 | J36: 25.08 | K36: 25.09 | L36: 25.10 | M36: 25.11 | N36: 25.12
A37: Workdays per month | B37: 2025 | C37: 22 | D37: 20 | E37: 21 | F37: 21 | G37: 20 | H37: 20 | I37: 23 | J37: 21 | K37: 22 | L37: 23 | M37: 20 | N37: 21
A38: R&P - pallets - inbound | B38: Budget | C38: 11407 | D38: 11407 | E38: 11407 | F38: 11407 | G38: 11407 | H38: 11407 | I38: 11407 | J38: 11407 | K38: 11407 | L38: 11407 | M38: 11407 | N38: 11407
A39: R&P - pallets - inbound | B39: Actual | C39: 10592 | D39: 11796 | E39: 13061 | F39: 12720 | G39: 13513 | H39: 13250 | I39: 14918 | J39: 16157 | K39: 12731 | L39: 14547 | M39: 13467
A40: R&P - pallets - inbound | B40: Delta | C40: =C39-C38 -> -815 | D40: =D39-D38 -> 389 | E40: =E39-E38 -> 1654 | F40: =F38-F39 -> -1313 | G40: =G38-G39 -> -2106 | H40: =H38-H39 -> -1843 | I40: =I38-I39 -> -3511 | J40: =J38-J39 -> -4750 | K40: =K38-K39 -> -1324 | L40: =L38-L39 -> -3140 | M40: =M39-M38 -> 2060 | N40: =N38-N39 -> 11407
A42: R&P - pallets - outbound | B42: Budget | C42: 9229 | D42: 9229 | E42: 9229 | F42: 9229 | G42: 9229 | H42: 9229 | I42: 9229 | J42: 9229 | K42: 9229 | L42: 9229 | M42: 9229 | N42: 9229
A43: R&P - pallets - outbound | B43: Actual | C43: 9813 | D43: 10901 | E43: 14488 | F43: 11669 | G43: 15078 | H43: 12132 | I43: 13910 | J43: 14325 | K43: 11466 | L43: 14809 | M43: 14403
A44: R&P - pallets - outbound | B44: Delta | C44: =C43-C42 -> 584 | D44: =D43-D42 -> 1672 | E44: =E43-E42 -> 5259 | F44: =F42-F43 -> -2440 | G44: =G42-G43 -> -5849 | H44: =H42-H43 -> -2903 | I44: =I42-I43 -> -4681 | J44: =J42-J43 -> -5096 | K44: =K42-K43 -> -2237 | L44: =L42-L43 -> -5580 | M44: =M43-M42 -> 5174 | N44: =N42-N43 -> 9229
A46: FG - pallets - inbound | B46: Budget | C46: =27.5*21.75*47 -> 28111.875 | D46: =27.5*21.75*47 -> 28111.875 | E46: =27.5*21.75*47 -> 28111.875 | F46: =27.5*21.75*47 -> 28111.875 | G46: =27.5*21.75*47 -> 28111.875 | H46: =27.5*21.75*47 -> 28111.875 | I46: =27.5*21.75*47 -> 28111.875 | J46: =27.5*21.75*47 -> 28111.875 | ... N46: =27.5*21.75*47 -> 28111.875
A47: FG - pallets - inbound | B47: Actual | C47: =30259+793 -> 31052 | D47: 25857 | E47: =26212+492 -> 26704 | F47: =29979+476 -> 30455 | G47: =32011+581 -> 32592 | H47: 26875 | I47: =31724+585 -> 32309 | J47: =545+27106 -> 27651 | K47: =27803+447 -> 28250 | L47: =29865+440 -> 30305 | M47: =29388+378 -> 29766
A48: FG - pallets - inbound | B48: Delta | C48: =C47-C46 -> 2940.125 | D48: =D47-D46 -> -2254.875 | E48: =E47-E46 -> -1407.875 | F48: =F47-F46 -> 2343.125 | G48: =G47-G46 -> 4480.125 | H48: =H47-H46 -> -1236.875 | I48: =I47-I46 -> 4197.125 | J48: =J47-J46 -> -460.875 | ... M48: =M47-M46 -> 1654.125
A50: FG - tu - outbound | B50: Budget | C50: 2551070.9 | D50: 2551070.9 | E50: 2551070.9 | F50: 2551070.9 | G50: 2551070.9 | H50: 2551070.9 | I50: 2551070.9 | J50: 2551070.9 | K50: 2551070.9 | L50: 2551070.9 | M50: 2551070.9 | N50: 2551070.9
A51: FG - tu - outbound | B51: Actual | C51: 3074478 | D51: 2826868 | E51: 2974974 | F51: 2600503 | G51: 2733361 | H51: 2771175 | I51: 3047037 | J51: 2803704 | K51: 2913508 | L51: 2860773 | M51: 2396557
A52: FG - tu - outbound | B52: Delta | C52: =C51-C50 -> 523407.12 | D52: =D51-D50 -> 275797.12 | E52: =E51-E50 -> 423903.12 | F52: =F51-F50 -> 49432.12 | G52: =G51-G50 -> 182290.12 | H52: =H51-H50 -> 220104.12 | I52: =I51-I50 -> 495966.12 | J52: =J51-J50 -> 252633.12 | ... M52: =M51-M50 -> -154513.88
...

Sheet 2024
A1: Variable labor KPI sheet
A5: Hours - total | C5: 24.01 | D5: 24.02 | E5: 24.03 | F5: 24.04 | G5: 24.05 | H5: 24.06 | I5: 24.07 | J5: 24.08 | K5: 24.09 | L5: 24.10 | M5: 24.11 | N5: 24.12
A7: Hours own personnel | B7: Actual | C7: =C9-C8 -> 7908 | D7: =D9-D8 -> 7457 | E7: =E9-E8 -> 8064 | F7: =F9-F8 -> 10246 | G7: =G9-G8 -> 9947 | H7: =H9-H8 -> 9577.16 | I7: =I9-I8 -> 12040.51 | J7: =J9-J8 -> 11018 | ... N7: =N9-N8 -> 11442
A8: Hours temp personnel | B8: Actual | C8: 23685 | D8: 22004 | E8: 18382 | F8: 17135 | G8: 18519 | H8: 18977.84 | I8: 23722.49 | J8: 21395 | K8: 19078 | L8: 21931 | M8: 20356 | N8: 19109
A9: Total | B9: Actual | C9: 31593 | D9: 29461 | E9: 26446 | F9: 27381 | G9: 28466 | H9: 28555 | I9: 35763 | J9: 32413 | K9: 29789 | L9: 33508 | M9: 33773 | N9: 30551
A10: Hours converted to FTE | B10: Actual | C10: =C9/C30/8 -> 179.50568 | D10: =D9/D30/8 -> 175.3631 | E10: =E9/E30/8 -> 157.41667 | F10: =F9/F30/8 -> 162.98214 | G10: =G9/G30/8 -> 169.44048 | H10: =H9/H30/8 -> 178.46875 | I10: =I9/I30/8 -> 194.36413 | J10: =J9/J30/8 -> 184.16477 | ... N10: =N9/N30/8 -> 190.94375
A12: Hours R&P | B12: Actual | I12: 392.05 | J12: 1503.7667 | K12: 2840.1667 | L12: 2954.1167 | M12: 3298.1167 | N12: 3182.7167
A13: Hours FG | B13: Actual | C13: 23037.083 | D13: 22602.767 | E13: 20153.617 | F13: 21223.967 | G13: 22162.083 | H13: 21604.867 | I13: 26363.85 | J13: 23940.45 | K13: 19680.017 | L13: 22429.317 | M13: 23351.4 | N13: 21921.2
A14: Hours VAL | B14: Actual | C14: 7682.2 | D14: 6051.5667 | E14: 4879.4833 | F14: 5407.4667 | G14: 5385.8333 | H14: 5849.3167 | I14: 7216.9 | J14: 5662 | K14: 6216.4333 | L14: 7096.8667 | M14: 5608.6167 | N14: 4196.9
A15: Hours Other | B15: Actual | C15: =C9-C14-C13-C12 -> 873.71667 | D15: =D9-D14-D13-D12 -> 806.66667 | E15: =E9-E14-E13-E12 -> 1412.9 | F15: =F9-F14-F13-F12 -> 749.56667 | G15: =G9-G14-G13-G12 -> 918.08333 | H15: =H9-H14-H13-H12 -> 1100.8167 | I15: =I9-I14-I13-I12 -> 1790.2 | J15: =J9-J14-J13-J12 -> 1306.7833 | ... N15: =N9-N14-N13-N12 -> 1250.1833
A19: Sickrate | C19: =C5 -> 24.01 | D19: =D5 -> 24.02 | E19: =E5 -> 24.03 | F19: =F5 -> 24.04 | G19: =G5 -> 24.05 | H19: =H5 -> 24.06 | I19: =I5 -> 24.07 | J19: =J5 -> 24.08 | ... N19: =N5 -> 24.12
A20: Sickrate blue collars | B20: Budget | C20: 0.05 | D20: 0.05 | E20: 0.05 | F20: 0.05 | G20: 0.05 | H20: 0.05 | I20: 0.05 | J20: 0.05 | K20: 0.05 | L20: 0.05 | M20: 0.05 | N20: 0.05
A21: Sickrate blue collars | B21: Actual | C21: 0.052901441 | D21: 0.032857942 | E21: 0.03659071 | F21: 0.029036005 | G21: 0.0501822 | H21: 0.037198391 | I21: 0.04522704 | J21: 0.04570672 | K21: 0.047179788 | L21: 0.054864667 | M21: 0.081121558 | N21: 0.071756602
A24: Costs | C24: =C19 -> 24.01 | D24: =D19 -> 24.02 | E24: =E19 -> 24.03 | F24: =F19 -> 24.04 | G24: =G19 -> 24.05 | H24: =H19 -> 24.06 | I24: =I19 -> 24.07 | J24: =J19 -> 24.08 | ... N24: =N19 -> 24.12
A25: Costs - total | B25: Actual | C25: 893825.44 | D25: 905532.79 | E25: 617589.28 | F25: 740448.14 | G25: 830544.96 | H25: 813661.83 | I25: 1056104 | J25: 939875.94 | K25: 902914.68 | L25: 949451.37 | M25: 1012199.6 | N25: 941341.83
A26: Costs / worked hour | C26: =(C25/C9) -> 28.291882 | D26: =(D25/D9) -> 30.736662 | E26: =(E25/E9) -> 23.352843 | F26: =(F25/F9) -> 27.042407 | G26: =(G25/G9) -> 29.176736 | H26: =(H25/H9) -> 28.494548 | I26: =(I25/I9) -> 29.530632 | J26: =(J25/J9) -> 28.996882 | ... N26: =(N25/N9) -> 30.812145
A29: Admin staff | C29: =C5 -> 24.01 | D29: =D5 -> 24.02 | E29: =E5 -> 24.03 | F29: =F5 -> 24.04 | G29: =G5 -> 24.05 | H29: =H5 -> 24.06 | I29: =I5 -> 24.07 | J29: =J5 -> 24.08 | ... N29: =N5 -> 24.12
A30: Workdays per month | B30: 2024 | C30: 22 | D30: 21 | E30: 21 | F30: 21 | G30: 21 | H30: 20 | I30: 23 | J30: 22 | K30: 21 | L30: 23 | M30: 21 | N30: 20
A31: FTE | C31: 28.3 | D31: 26.4 | E31: 26.4 | F31: 31.4 | G31: 31.4 | H31: 31.4 | I31: 29.4 | J31: 27.4 | K31: 28.4 | L31: 27.6 | M31: 29.6 | N31: 27.7

Sheet Powerbi Source
A1: Year | B1: Month | C1: Working day | D1: State | E1: Category | F1: Inbound/Outbound | G1: Pallet | H1: Working hour | I1: FTE | J1: Cost per working hour | K1: Cost | L1: Pallet per hour | M1: Pallet per day | N1: Pallet per FTE | O1: Cost per pallet | P1: Flexible
A2: 2025 | B2: 1 | C2: 22 | D2: Budget | E2: R&P | F2: Inbound | G2: ='Hours & volumes per subgroup'!C38 -> 11407 | H2: =H6*'Powerbi Source'!$G2/G6 -> 1961.2977 | I2: =I6*'Powerbi Source'!$G2/G6 -> 11.143737 | J2: =Topsheet!C30 -> 29.526829 | K2: ='Powerbi Source'!$H2*'Powerbi Source'!$J2 -> 57910.902 | L2: ='Powerbi Source'!$G2/'Powerbi Source'!$H2 -> 5.8160471 | M2: ='Powerbi Source'!$G2/'Powerbi Source'!$C2 -> 518.5 | N2: ='Powerbi Source'!$G2/'Powerbi Source'!$I2 -> 1023.6243 | O2: =IFERROR('Powerbi Source'!$K2/'Powerbi Source'!$G2,0) -> 5.0767864
A3: 2025 | B3: 1 | C3: 22 | D3: Actual | E3: R&P | F3: Inbound | G3: ='Hours & volumes per subgroup'!C39 -> 10592 | H3: =H7*'Powerbi Source'!$G3/G7 -> 1892.0774 | I3: =I7*'Powerbi Source'!$G3/G7 -> 10.75044 | J3: =J2 -> 29.526829 | K3: ='Powerbi Source'!$H3*'Powerbi Source'!$J3 -> 55867.046 | L3: ='Powerbi Source'!$G3/'Powerbi Source'!$H3 -> 5.5980796 | M3: ='Powerbi Source'!$G3/'Powerbi Source'!$C3 -> 481.45455 | N3: ='Powerbi Source'!$G3/'Powerbi Source'!$I3 -> 985.262 | O3: =IFERROR('Powerbi Source'!$K3/'Powerbi Source'!$G3,0) -> 5.2744568
A4: 2025 | B4: 1 | C4: 22 | D4: Budget | E4: R&P | F4: Outbound | G4: ='Hours & volumes per subgroup'!C42 -> 9229 | H4: =H6*'Powerbi Source'!$G4/G6 -> 1586.8166 | I4: =I6*'Powerbi Source'!$G4/G6 -> 9.0160034 | J4: =J3 -> 29.526829 | K4: ='Powerbi Source'!$H4*'Powerbi Source'!$J4 -> 46853.661 | L4: ='Powerbi Source'!$G4/'Powerbi Source'!$H4 -> 5.8160471 | M4: ='Powerbi Source'!$G4/'Powerbi Source'!$C4 -> 419.5 | N4: ='Powerbi Source'!$G4/'Powerbi Source'!$I4 -> 1023.6243 | O4: =IFERROR('Powerbi Source'!$K4/'Powerbi Source'!$G4,0) -> 5.0767864
A5: 2025 | B5: 1 | C5: 22 | D5: Actual | E5: R&P | F5: Outbound | G5: ='Hours & volumes per subgroup'!C43 -> 9813 | H5: =H7*'Powerbi Source'!$G5/G7 -> 1752.9226 | I5: =I7*'Powerbi Source'!$G5/G7 -> 9.9597873 | J5: =J4 -> 29.526829 | K5: ='Powerbi Source'!$H5*'Powerbi Source'!$J5 -> 51758.244 | L5: ='Powerbi Source'!$G5/'Powerbi Source'!$H5 -> 5.5980796 | M5: ='Powerbi Source'!$G5/'Powerbi Source'!$C5 -> 446.04545 | N5: ='Powerbi Source'!$G5/'Powerbi Source'!$I5 -> 985.262 | O5: =IFERROR('Powerbi Source'!$K5/'Powerbi Source'!$G5,0) -> 5.2744568
A6: 2025 | B6: 1 | C6: 22 | D6: Budget | E6: R&P | F6: Total | G6: =G2+G4 -> 20636 | H6: ='Hours & volumes per subgroup'!C2 -> 3548.1143 | I6: ='Hours & volumes per subgroup'!C20 -> 20.159741 | J6: =J5 -> 29.526829 | K6: ='Powerbi Source'!$H6*'Powerbi Source'!$J6 -> 104764.56 | L6: ='Powerbi Source'!$G6/'Powerbi Source'!$H6 -> 5.8160471 | M6: ='Powerbi Source'!$G6/'Powerbi Source'!$C6 -> 938 | N6: ='Powerbi Source'!$G6/'Powerbi Source'!$I6 -> 1023.6243 | O6: =IFERROR('Powerbi Source'!$K6/'Powerbi Source'!$G6,0) -> 5.0767864
A7: 2025 | B7: 1 | C7: 22 | D7: Actual | E7: R&P | F7: Total | G7: =G3+G5 -> 20405 | H7: ='Hours & volumes per subgroup'!C3 -> 3645 | I7: ='Hours & volumes per subgroup'!C21 -> 20.710227 | J7: =J6 -> 29.526829 | K7: ='Powerbi Source'!$H7*'Powerbi Source'!$J7 -> 107625.29 | L7: ='Powerbi Source'!$G7/'Powerbi Source'!$H7 -> 5.5980796 | M7: ='Powerbi Source'!$G7/'Powerbi Source'!$C7 -> 927.5 | N7: ='Powerbi Source'!$G7/'Powerbi Source'!$I7 -> 985.262 | O7: =IFERROR('Powerbi Source'!$K7/'Powerbi Source'!$G7,0) -> 5.2744568
A8: 2025 | B8: 1 | C8: 22 | D8: Budget | E8: FG | F8: Inbound | G8: ='Hours & volumes per subgroup'!C46 -> 28111.875 | H8: =H12*'Powerbi Source'!$G8/G12 -> 10393.522 | I8: =I12*'Powerbi Source'!$G8/G12 -> 59.054104 | J8: =J7 -> 29.526829 | K8: ='Powerbi Source'!$H8*'Powerbi Source'!$J8 -> 306887.75 | L8: ='Powerbi Source'!$G8/'Powerbi Source'!$H8 -> 2.7047496 | M8: ='Powerbi Source'!$G8/'Powerbi Source'!$C8 -> 1277.8125 | N8: ='Powerbi Source'!$G8/'Powerbi Source'!$I8 -> 476.03592 | O8: =IFERROR('Powerbi Source'!$K8/'Powerbi Source'!$G8,0) -> 10.916659
A9: 2025 | B9: 1 | C9: 22 | D9: Actual | E9: FG | F9: Inbound | G9: ='Hours & volumes per subgroup'!C47 -> 31052 | H9: =H13*'Powerbi Source'!$G9/G13 -> 10656.432 | I9: =I13*'Powerbi Source'!$G9/G13 -> 60.547911 | J9: =J8 -> 29.526829 | K9: ='Powerbi Source'!$H9*'Powerbi Source'!$J9 -> 314650.65 | L9: ='Powerbi Source'!$G9/'Powerbi Source'!$H9 -> 2.9139208 | M9: ='Powerbi Source'!$G9/'Powerbi Source'!$C9 -> 1411.4545 | N9: ='Powerbi Source'!$G9/'Powerbi Source'!$I9 -> 512.85006 | O9: =IFERROR('Powerbi Source'!$K9/'Powerbi Source'!$G9,0) -> 10.133024
A10: 2025 | B10: 1 | C10: 22 | D10: Budget | E10: FG | F10: Outbound | G10: ='Hours & volumes per subgroup'!C50/90 -> 28345.232 | H10: =H12*'Powerbi Source'!$G10/G12 -> 10479.799 | I10: =I12*'Powerbi Source'!$G10/G12 -> 59.544313 | J10: =J9 -> 29.526829 | K10: ='Powerbi Source'!$H10*'Powerbi Source'!$J10 -> 309435.23 | L10: ='Powerbi Source'!$G10/'Powerbi Source'!$H10 -> 2.7047496 | M10: ='Powerbi Source'!$G10/'Powerbi Source'!$C10 -> 1288.4196 | N10: ='Powerbi Source'!$G10/'Powerbi Source'!$I10 -> 476.03592 | O10: =IFERROR('Powerbi Source'!$K10/'Powerbi Source'!$G10,0) -> 10.916659
A11: 2025 | B11: 1 | C11: 22 | D11: Actual | E11: FG | F11: Outbound | G11: ='Hours & volumes per subgroup'!C53 -> 34654 | H11: =H13*'Powerbi Source'!$G11/G13 -> 11892.568 | I11: =I13*'Powerbi Source'!$G11/G13 -> 67.571407 | J11: =J10 -> 29.526829 | K11: ='Powerbi Source'!$H11*'Powerbi Source'!$J11 -> 351149.8 | L11: ='Powerbi Source'!$G11/'Powerbi Source'!$H11 -> 2.9139208 | M11: ='Powerbi Source'!$G11/'Powerbi Source'!$C11 -> 1575.1818 | N11: ='Powerbi Source'!$G11/'Powerbi Source'!$I11 -> 512.85006 | O11: =IFERROR('Powerbi Source'!$K11/'Powerbi Source'!$G11,0) -> 10.133024
A12: 2025 | B12: 1 | C12: 22 | D12: Budget | E12: FG | F12: Total | G12: =G8+G10 -> 56457.107 | H12: ='Hours & volumes per subgroup'!C10 -> 20873.321 | I12: ='Hours & volumes per subgroup'!C28 -> 118.59842 | J12: =J11 -> 29.526829 | K12: ='Powerbi Source'!$H12*'Powerbi Source'!$J12 -> 616322.98 | L12: ='Powerbi Source'!$G12/'Powerbi Source'!$H12 -> 2.7047496 | M12: ='Powerbi Source'!$G12/'Powerbi Source'!$C12 -> 2566.2321 | N12: ='Powerbi Source'!$G12/'Powerbi Source'!$I12 -> 476.03592 | O12: =IFERROR('Powerbi Source'!$K12/'Powerbi Source'!$G12,0) -> 10.916659
A13: 2025 | B13: 1 | C13: 22 | D13: Actual | E13: FG | F13: Total | G13: =G9+G11 -> 65706 | H13: ='Hours & volumes per subgroup'!C11 -> 22549 | I13: ='Hours & volumes per subgroup'!C29 -> 128.11932 | J13: =J12 -> 29.526829 | K13: ='Powerbi Source'!$H13*'Powerbi Source'!$J13 -> 665800.46 | L13: ='Powerbi Source'!$G13/'Powerbi Source'!$H13 -> 2.9139208 | M13: ='Powerbi Source'!$G13/'Powerbi Source'!$C13 -> 2986.6364 | N13: ='Powerbi Source'!$G13/'Powerbi Source'!$I13 -> 512.85006 | O13: =IFERROR('Powerbi Source'!$K13/'Powerbi Source'!$G13,0) -> 10.133024
A14: 2025 | B14: 1 | C14: 22 | D14: Budget | E14: VAL | F14: Total | G14: ='Hours & volumes per subgroup'!C55 -> 219409 | H14: ='Hours & volumes per subgroup'!C6 -> 6505.7103 | I14: ='Hours & volumes per subgroup'!C24 -> 36.964263 | J14: =J13 -> 29.526829 | K14: ='Powerbi Source'!$H14*'Powerbi Source'!$J14 -> 192092.99 | L14: ='Powerbi Source'!$G14/'Powerbi Source'!$H14 -> 33.725602 | M14: ='Powerbi Source'!$G14/'Powerbi Source'!$C14 -> 9973.1364 | N14: ='Powerbi Source'!$G14/'Powerbi Source'!$I14 -> 5935.706 | O14: =IFERROR('Powerbi Source'!$K14/'Powerbi Source'!$G14,0) -> 0.87550189
A15: 2025 | B15: 1 | C15: 22 | D15: Actual | E15: VAL | F15: Total | G15: ='Hours & volumes per subgroup'!C56 -> 209420 | H15: ='Hours & volumes per subgroup'!C7 -> 6034 | I15: ='Hours & volumes per subgroup'!C25 -> 34.284091 | J15: =J14 -> 29.526829 | K15: ='Powerbi Source'!$H15*'Powerbi Source'!$J15 -> 178164.88 | L15: ='Powerbi Source'!$G15/'Powerbi Source'!$H15 -> 34.706662 | M15: ='Powerbi Source'!$G15/'Powerbi Source'!$C15 -> 9519.0909 | N15: ='Powerbi Source'!$G15/'Powerbi Source'!$I15 -> 6108.3726 | O15: =IFERROR('Powerbi Source'!$K15/'Powerbi Source'!$G15,0) -> 0.85075391
A16: 2025 | B16: 1 | C16: 22 | D16: Budget | E16: Others | F16: Total | G16: 0 | H16: ='Hours & volumes per subgroup'!C14 -> 2302.0206 | I16: ='Hours & volumes per subgroup'!C32 -> 13.079662 | J16: =J15 -> 29.526829 | K16: ='Powerbi Source'!$H16*'Powerbi Source'!$J16 -> 67971.367 | L16: ='Powerbi Source'!$G16/'Powerbi Source'!$H16 -> 0 | M16: ='Powerbi Source'!$G16/'Powerbi Source'!$C16 -> 0 | N16: ='Powerbi Source'!$G16/'Powerbi Source'!$I16 -> 0 | O16: =IFERROR('Powerbi Source'!$K16/'Powerbi Source'!$G16,0) -> 0
A17: 2025 | B17: 1 | C17: 22 | D17: Actual | E17: Others | F17: Total | G17: 0 | H17: ='Hours & volumes per subgroup'!C15 -> 1132 | I17: ='Hours & volumes per subgroup'!C33 -> 6.4318182 | J17: =J16 -> 29.526829 | K17: ='Powerbi Source'!$H17*'Powerbi Source'!$J17 -> 33424.37 | L17: ='Powerbi Source'!$G17/'Powerbi Source'!$H17 -> 0 | M17: ='Powerbi Source'!$G17/'Powerbi Source'!$C17 -> 0 | N17: ='Powerbi Source'!$G17/'Powerbi Source'!$I17 -> 0 | O17: =IFERROR('Powerbi Source'!$K17/'Powerbi Source'!$G17,0) -> 0
A18: 2025 | B18: 2 | C18: 20 | D18: Budget | E18: R&P | F18: Inbound | G18: ='Hours & volumes per subgroup'!D38 -> 11407 | H18: =H22*'Powerbi Source'!$G18/G22 -> 1961.2977 | I18: =I22*'Powerbi Source'!$G18/G22 -> 12.258111 | J18: 28.703985 | K18: ='Powerbi Source'!$H18*'Powerbi Source'!$J18 -> 56297.06 | L18: ='Powerbi Source'!$G18/'Powerbi Source'!$H18 -> 5.8160471 | M18: ='Powerbi Source'!$G18/'Powerbi Source'!$C18 -> 570.35 | N18: ='Powerbi Source'!$G18/'Powerbi Source'!$I18 -> 930.56753 | O18: =IFERROR('Powerbi Source'!$K18/'Powerbi Source'!$G18,0) -> 4.9353082
A19: 2025 | B19: 2 | C19: 20 | D19: Actual | E19: R&P | F19: Inbound | G19: ='Hours & volumes per subgroup'!D39 -> 11796 | H19: =H23*'Powerbi Source'!$G19/G23 -> 2300.8996 | I19: =I23*'Powerbi Source'!$G19/G23 -> 14.380623 | J19: 28.703985 | K19: ='Powerbi Source'!$H19*'Powerbi Source'!$J19 -> 66044.988 | L19: ='Powerbi Source'!$G19/'Powerbi Source'!$H19 -> 5.1266904 | M19: ='Powerbi Source'!$G19/'Powerbi Source'!$C19 -> 589.8 | N19: ='Powerbi Source'!$G19/'Powerbi Source'!$I19 -> 820.27046 | O19: =IFERROR('Powerbi Source'!$K19/'Powerbi Source'!$G19,0) -> 5.5989308
A20: 2025 | B20: 2 | C20: 20 | D20: Budget | E20: R&P | F20: Outbound | G20: ='Hours & volumes per subgroup'!D42 -> 9229 | H20: =H22*'Powerbi Source'!$G20/G22 -> 1586.8166 | I20: =I22*'Powerbi Source'!$G20/G22 -> 9.9176037 | J20: 28.703985 | K20: ='Powerbi Source'!$H20*'Powerbi Source'!$J20 -> 45547.959 | L20: ='Powerbi Source'!$G20/'Powerbi Source'!$H20 -> 5.8160471 | M20: ='Powerbi Source'!$G20/'Powerbi Source'!$C20 -> 461.45 | N20: ='Powerbi Source'!$G20/'Powerbi Source'!$I20 -> 930.56753 | O20: =IFERROR('Powerbi Source'!$K20/'Powerbi Source'!$G20,0) -> 4.9353082
A21: 2025 | B21: 2 | C21: 20 | D21: Actual | E21: R&P | F21: Outbound | G21: ='Hours & volumes per subgroup'!C43 -> 9813 | H21: =H23*'Powerbi Source'!$G21/G23 -> 1914.1004 | I21: =I23*'Powerbi Source'!$G21/G23 -> 11.963127 | J21: 28.703985 | K21: ='Powerbi Source'!$H21*'Powerbi Source'!$J21 -> 54942.308 | L21: ='Powerbi Source'!$G21/'Powerbi Source'!$H21 -> 5.1266904 | M21: ='Powerbi Source'!$G21/'Powerbi Source'!$C21 -> 490.65 | N21: ='Powerbi Source'!$G21/'Powerbi Source'!$I21 -> 820.27046 | O21: =IFERROR('Powerbi Source'!$K21/'Powerbi Source'!$G21,0) -> 5.5989308
A22: 2025 | B22: 2 | C22: 20 | D22: Budget | E22: R&P | F22: Total | G22: =G18+G20 -> 20636 | H22: ='Hours & volumes per subgroup'!D2 -> 3548.1143 | I22: ='Hours & volumes per subgroup'!D20 -> 22.175715 | J22: 28.703985 | K22: ='Powerbi Source'!$H22*'Powerbi Source'!$J22 -> 101845.02 | L22: ='Powerbi Source'!$G22/'Powerbi Source'!$H22 -> 5.8160471 | M22: ='Powerbi Source'!$G22/'Powerbi Source'!$C22 -> 1031.8 | N22: ='Powerbi Source'!$G22/'Powerbi Source'!$I22 -> 930.56753 | O22: =IFERROR('Powerbi Source'!$K22/'Powerbi Source'!$G22,0) -> 4.9353082
A23: 2025 | B23: 2 | C23: 20 | D23: Actual | E23: R&P | F23: Total | G23: =G19+G21 -> 21609 | H23: ='Hours & volumes per subgroup'!D3 -> 4215 | I23: ='Hours & volumes per subgroup'!D21 -> 26.34375 | J23: 28.703985 | K23: ='Powerbi Source'!$H23*'Powerbi Source'!$J23 -> 120987.3 | L23: ='Powerbi Source'!$G23/'Powerbi Source'!$H23 -> 5.1266904 | M23: ='Powerbi Source'!$G23/'Powerbi Source'!$C23 -> 1080.45 | N23: ='Powerbi Source'!$G23/'Powerbi Source'!$I23 -> 820.27046 | O23: =IFERROR('Powerbi Source'!$K23/'Powerbi Source'!$G23,0) -> 5.5989308
A24: 2025 | B24: 2 | C24: 20 | D24: Budget | E24: FG | F24: Inbound | G24: ='Hours & volumes per subgroup'!D46 -> 28111.875 | H24: =H28*'Powerbi Source'!$G24/G28 -> 10393.522 | I24: =I28*'Powerbi Source'!$G24/G28 -> 64.959515 | J24: 28.703985 | K24: ='Powerbi Source'!$H24*'Powerbi Source'!$J24 -> 298335.51 | L24: ='Powerbi Source'!$G24/'Powerbi Source'!$H24 -> 2.7047496 | M24: ='Powerbi Source'!$G24/'Powerbi Source'!$C24 -> 1405.5938 | N24: ='Powerbi Source'!$G24/'Powerbi Source'!$I24 -> 432.75993 | O24: =IFERROR('Powerbi Source'!$K24/'Powerbi Source'!$G24,0) -> 10.612437
A25: 2025 | B25: 2 | C25: 20 | D25: Actual | E25: FG | F25: Inbound | G25: ='Hours & volumes per subgroup'!D47 -> 25857 | H25: =H29*'Powerbi Source'!$G25/G29 -> 8660.4453 | I25: =I29*'Powerbi Source'!$G25/G29 -> 54.127783 | J25: 28.703985 | K25: ='Powerbi Source'!$H25*'Powerbi Source'!$J25 -> 248589.29 | L25: ='Powerbi Source'!$G25/'Powerbi Source'!$H25 -> 2.9856432 | M25: ='Powerbi Source'!$G25/'Powerbi Source'!$C25 -> 1292.85 | N25: ='Powerbi Source'!$G25/'Powerbi Source'!$I25 -> 477.70292 | O25: =IFERROR('Powerbi Source'!$K25/'Powerbi Source'!$G25,0) -> 9.6140036
A26: 2025 | B26: 2 | C26: 20 | D26: Budget | E26: FG | F26: Outbound | G26: ='Hours & volumes per subgroup'!D50/90 -> 28345.232 | H26: =H28*'Powerbi Source'!$G26/G28 -> 10479.799 | I26: =I28*'Powerbi Source'!$G26/G28 -> 65.498744 | J26: 28.703985 | K26: ='Powerbi Source'!$H26*'Powerbi Source'!$J26 -> 300811.99 | L26: ='Powerbi Source'!$G26/'Powerbi Source'!$H26 -> 2.7047496 | M26: ='Powerbi Source'!$G26/'Powerbi Source'!$C26 -> 1417.2616 | N26: ='Powerbi Source'!$G26/'Powerbi Source'!$I26 -> 432.75993 | O26: =IFERROR('Powerbi Source'!$K26/'Powerbi Source'!$G26,0) -> 10.612437
A27: 2025 | B27: 2 | C27: 20 | D27: Actual | E27: FG | F27: Outbound | G27: ='Hours & volumes per subgroup'!D53 -> 32372 | H27: =H29*'Powerbi Source'!$G27/G29 -> 10842.555 | I27: =I29*'Powerbi Source'!$G27/G29 -> 67.765967 | J27: 28.703985 | K27: ='Powerbi Source'!$H27*'Powerbi Source'!$J27 -> 311224.52 | L27: ='Powerbi Source'!$G27/'Powerbi Source'!$H27 -> 2.9856432 | M27: ='Powerbi Source'!$G27/'Powerbi Source'!$C27 -> 1618.6 | N27: ='Powerbi Source'!$G27/'Powerbi Source'!$I27 -> 477.70292 | O27: =IFERROR('Powerbi Source'!$K27/'Powerbi Source'!$G27,0) -> 9.6140036
A28: 2025 | B28: 2 | C28: 20 | D28: Budget | E28: FG | F28: Total | G28: =G24+G26 -> 56457.107 | H28: ='Hours & volumes per subgroup'!D10 -> 20873.321 | I28: ='Hours & volumes per subgroup'!D28 -> 130.45826 | J28: 28.703985 | K28: ='Powerbi Source'!$H28*'Powerbi Source'!$J28 -> 599147.5 | L28: ='Powerbi Source'!$G28/'Powerbi Source'!$H28 -> 2.7047496 | M28: ='Powerbi Source'!$G28/'Powerbi Source'!$C28 -> 2822.8553 | N28: ='Powerbi Source'!$G28/'Powerbi Source'!$I28 -> 432.75993 | O28: =IFERROR('Powerbi Source'!$K28/'Powerbi Source'!$G28,0) -> 10.612437
A29: 2025 | B29: 2 | C29: 20 | D29: Actual | E29: FG | F29: Total | G29: =G25+G27 -> 58229 | H29: ='Hours & volumes per subgroup'!D11 -> 19503 | I29: ='Hours & volumes per subgroup'!D29 -> 121.89375 | J29: 28.703985 | K29: ='Powerbi Source'!$H29*'Powerbi Source'!$J29 -> 559813.81 | L29: ='Powerbi Source'!$G29/'Powerbi Source'!$H29 -> 2.9856432 | M29: ='Powerbi Source'!$G29/'Powerbi Source'!$C29 -> 2911.45 | N29: ='Powerbi Source'!$G29/'Powerbi Source'!$I29 -> 477.70292 | O29: =IFERROR('Powerbi Source'!$K29/'Powerbi Source'!$G29,0) -> 9.6140036
A30: 2025 | B30: 2 | C30: 20 | D30: Budget | E30: VAL | F30: Total | G30: ='Hours & volumes per subgroup'!D55 -> 219409 | H30: ='Hours & volumes per subgroup'!D6 -> 6505.7103 | I30: ='Hours & volumes per subgroup'!D24 -> 40.66069 | J30: 28.703985 | K30: ='Powerbi Source'!$H30*'Powerbi Source'!$J30 -> 186739.81 | L30: ='Powerbi Source'!$G30/'Powerbi Source'!$H30 -> 33.725602 | M30: ='Powerbi Source'!$G30/'Powerbi Source'!$C30 -> 10970.45 | N30: ='Powerbi Source'!$G30/'Powerbi Source'!$I30 -> 5396.0964 | O30: =IFERROR('Powerbi Source'!$K30/'Powerbi Source'!$G30,0) -> 0.85110369
A31: 2025 | B31: 2 | C31: 20 | D31: Actual | E31: VAL | F31: Total | G31: ='Hours & volumes per subgroup'!D56 -> 180990 | H31: ='Hours & volumes per subgroup'!D7 -> 5875 | I31: ='Hours & volumes per subgroup'!D25 -> 36.71875 | J31: 28.703985 | K31: ='Powerbi Source'!$H31*'Powerbi Source'!$J31 -> 168635.91 | L31: ='Powerbi Source'!$G31/'Powerbi Source'!$H31 -> 30.806809 | M31: ='Powerbi Source'!$G31/'Powerbi Source'!$C31 -> 9049.5 | N31: ='Powerbi Source'!$G31/'Powerbi Source'!$I31 -> 4929.0894 | O31: =IFERROR('Powerbi Source'!$K31/'Powerbi Source'!$G31,0) -> 0.93174159
A32: 2025 | B32: 2 | C32: 20 | D32: Budget | E32: Others | F32: Total | G32: 0 | H32: ='Hours & volumes per subgroup'!D14 -> 2302.0206 | I32: ='Hours & volumes per subgroup'!D32 -> 14.387629 | J32: 28.703985 | K32: ='Powerbi Source'!$H32*'Powerbi Source'!$J32 -> 66077.164 | L32: ='Powerbi Source'!$G32/'Powerbi Source'!$H32 -> 0 | M32: ='Powerbi Source'!$G32/'Powerbi Source'!$C32 -> 0 | N32: ='Powerbi Source'!$G32/'Powerbi Source'!$I32 -> 0 | O32: =IFERROR('Powerbi Source'!$K32/'Powerbi Source'!$G32,0) -> 0
A33: 2025 | B33: 2 | C33: 20 | D33: Actual | E33: Others | F33: Total | G33: 0 | H33: ='Hours & volumes per subgroup'!D15 -> 1250 | I33: ='Hours & volumes per subgroup'!D33 -> 7.8125 | J33: 28.703985 | K33: ='Powerbi Source'!$H33*'Powerbi Source'!$J33 -> 35879.981 | L33: ='Powerbi Source'!$G33/'Powerbi Source'!$H33 -> 0 | M33: ='Powerbi Source'!$G33/'Powerbi Source'!$C33 -> 0 | N33: ='Powerbi Source'!$G33/'Powerbi Source'!$I33 -> 0 | O33: =IFERROR('Powerbi Source'!$K33/'Powerbi Source'!$G33,0) -> 0
A34: 2025 | B34: 3 | C34: 21 | D34: Budget | E34: R&P | F34: Inbound | G34: ='Hours & volumes per subgroup'!E38 -> 11407 | H34: =H38*'Powerbi Source'!$G34/G38 -> 1961.2977 | I34: =I38*'Powerbi Source'!$G34/G38 -> 11.674391 | J34: 29.049874 | K34: ='Powerbi Source'!$H34*'Powerbi Source'!$J34 -> 56975.453 | L34: ='Powerbi Source'!$G34/'Powerbi Source'!$H34 -> 5.8160471 | M34: ='Powerbi Source'!$G34/'Powerbi Source'!$C34 -> 543.19048 | N34: ='Powerbi Source'!$G34/'Powerbi Source'!$I34 -> 977.09591 | O34: =IFERROR('Powerbi Source'!$K34/'Powerbi Source'!$G34,0) -> 4.9947798
A35: 2025 | B35: 3 | C35: 21 | D35: Actual | E35: R&P | F35: Inbound | G35: ='Hours & volumes per subgroup'!E39 -> 13061 | H35: =H39*'Powerbi Source'!$G35/G39 -> 2268.5718 | I35: =I39*'Powerbi Source'!$G35/G39 -> 13.503404 | J35: 29.049874 | K35: ='Powerbi Source'!$H35*'Powerbi Source'!$J35 -> 65901.726 | L35: ='Powerbi Source'!$G35/'Powerbi Source'!$H35 -> 5.7573668 | M35: ='Powerbi Source'!$G35/'Powerbi Source'!$C35 -> 621.95238 | N35: ='Powerbi Source'!$G35/'Powerbi Source'!$I35 -> 967.23762 | O35: =IFERROR('Powerbi Source'!$K35/'Powerbi Source'!$G35,0) -> 5.0456876
A36: 2025 | B36: 3 | C36: 21 | D36: Budget | E36: R&P | F36: Outbound | G36: ='Hours & volumes per subgroup'!E42 -> 9229 | H36: =H38*'Powerbi Source'!$G36/G38 -> 1586.8166 | I36: =I38*'Powerbi Source'!$G36/G38 -> 9.4453369 | J36: 29.049874 | K36: ='Powerbi Source'!$H36*'Powerbi Source'!$J36 -> 46096.823 | L36: ='Powerbi Source'!$G36/'Powerbi Source'!$H36 -> 5.8160471 | M36: ='Powerbi Source'!$G36/'Powerbi Source'!$C36 -> 439.47619 | N36: ='Powerbi Source'!$G36/'Powerbi Source'!$I36 -> 977.09591 | O36: =IFERROR('Powerbi Source'!$K36/'Powerbi Source'!$G36,0) -> 4.9947798
A37: 2025 | B37: 3 | C37: 21 | D37: Actual | E37: R&P | F37: Outbound | G37: ='Hours & volumes per subgroup'!E43 -> 14488 | H37: =H39*'Powerbi Source'!$G37/G39 -> 2516.4282 | I37: =I39*'Powerbi Source'!$G37/G39 -> 14.978739 | J37: 29.049874 | K37: ='Powerbi Source'!$H37*'Powerbi Source'!$J37 -> 73101.923 | L37: ='Powerbi Source'!$G37/'Powerbi Source'!$H37 -> 5.7573668 | M37: ='Powerbi Source'!$G37/'Powerbi Source'!$C37 -> 689.90476 | N37: ='Powerbi Source'!$G37/'Powerbi Source'!$I37 -> 967.23762 | O37: =IFERROR('Powerbi Source'!$K37/'Powerbi Source'!$G37,0) -> 5.0456876
A38: 2025 | B38: 3 | C38: 21 | D38: Budget | E38: R&P | F38: Total | G38: =G34+G36 -> 20636 | H38: ='Hours & volumes per subgroup'!E2 -> 3548.1143 | I38: ='Hours & volumes per subgroup'!E20 -> 21.119728 | J38: 29.049874 | K38: ='Powerbi Source'!$H38*'Powerbi Source'!$J38 -> 103072.28 | L38: ='Powerbi Source'!$G38/'Powerbi Source'!$H38 -> 5.8160471 | M38: ='Powerbi Source'!$G38/'Powerbi Source'!$C38 -> 982.66667 | N38: ='Powerbi Source'!$G38/'Powerbi Source'!$I38 -> 977.09591 | O38: =IFERROR('Powerbi Source'!$K38/'Powerbi Source'!$G38,0) -> 4.9947798
A39: 2025 | B39: 3 | C39: 21 | D39: Actual | E39: R&P | F39: Total | G39: =G35+G37 -> 27549 | H39: ='Hours & volumes per subgroup'!E3 -> 4785 | I39: ='Hours & volumes per subgroup'!E21 -> 28.482143 | J39: 29.049874 | K39: ='Powerbi Source'!$H39*'Powerbi Source'!$J39 -> 139003.65 | L39: ='Powerbi Source'!$G39/'Powerbi Source'!$H39 -> 5.7573668 | M39: ='Powerbi Source'!$G39/'Powerbi Source'!$C39 -> 1311.8571 | N39: ='Powerbi Source'!$G39/'Powerbi Source'!$I39 -> 967.23762 | O39: =IFERROR('Powerbi Source'!$K39/'Powerbi Source'!$G39,0) -> 5.0456876
A40: 2025 | B40: 3 | C40: 21 | D40: Budget | E40: FG | F40: Inbound | G40: ='Hours & volumes per subgroup'!E46 -> 28111.875 | H40: =H44*'Powerbi Source'!$G40/G44 -> 10393.522 | I40: =I44*'Powerbi Source'!$G40/G44 -> 61.866204 | J40: 29.049874 | K40: ='Powerbi Source'!$H40*'Powerbi Source'!$J40 -> 301930.52 | L40: ='Powerbi Source'!$G40/'Powerbi Source'!$H40 -> 2.7047496 | M40: ='Powerbi Source'!$G40/'Powerbi Source'!$C40 -> 1338.6607 | N40: ='Powerbi Source'!$G40/'Powerbi Source'!$I40 -> 454.39793 | O40: =IFERROR('Powerbi Source'!$K40/'Powerbi Source'!$G40,0) -> 10.740319
...

Sheet Aggregate_data
A1: Year | B1: Month | C1: Working day | D1: Category | E1: Inbound/Outbound | F1: Pallet | G1: Working hour | H1: FTE | I1: Cost per working hour | J1: Cost | K1: Pallet per hour per FTE | L1: Pallet per day | M1: Pallet per FTE | N1: Cost per pallet | O1: Pallet (budget) | P1: Working hour (budget) | Q1: FTE (budget) | R1: Cost per working hour (budget) | S1: Cost (budget) | T1: Pallet per hour (budget) | U1: Pallet per day (budget) | V1: Pallet per FTE (budget) | W1: Cost per pallet (budget) | X1: Flexible
A2: 2025 | B2: 1 | C2: 22 | D2: R&P | E2: Inbound | F2: 10592 | G2: 1892.0774 | H2: 10.75044 | I2: 29.526829 | J2: 55867.046 | K2: 5.5980796 | L2: 481.45455 | M2: 985.262 | N2: 5.2744568 | O2: 11407 | P2: 1961.2977 | Q2: 11.143737 | R2: 29.526829 | S2: 57910.902 | T2: 5.8160471 | U2: 518.5 | V2: 1023.6243 | W2: 5.0767864
A3: 2025 | B3: 1 | C3: 22 | D3: R&P | E3: Outbound | F3: 9813 | G3: 1752.9226 | H3: 9.9597873 | I3: 29.526829 | J3: 51758.244 | K3: 5.5980796 | L3: 446.04545 | M3: 985.262 | N3: 5.2744568 | O3: 9229 | P3: 1586.8166 | Q3: 9.0160034 | R3: 29.526829 | S3: 46853.661 | T3: 5.8160471 | U3: 419.5 | V3: 1023.6243 | W3: 5.0767864
A4: 2025 | B4: 1 | C4: 22 | D4: R&P | E4: Total | F4: 20405 | G4: 3645 | H4: 20.710227 | I4: 29.526829 | J4: 107625.29 | K4: 5.5980796 | L4: 927.5 | M4: 985.262 | N4: 5.2744568 | O4: 20636 | P4: 3548.1143 | Q4: 20.159741 | R4: 29.526829 | S4: 104764.56 | T4: 5.8160471 | U4: 938 | V4: 1023.6243 | W4: 5.0767864
A5: 2025 | B5: 1 | C5: 22 | D5: FG | E5: Inbound | F5: 31052 | G5: 10656.432 | H5: 60.547911 | I5: 29.526829 | J5: 314650.65 | K5: 2.9139208 | L5: 1411.4545 | M5: 512.85006 | N5: 10.133024 | O5: 28111.875 | P5: 10393.522 | Q5: 59.054104 | R5: 29.526829 | S5: 306887.75 | T5: 2.7047496 | U5: 1277.8125 | V5: 476.03592 | W5: 10.916659
A6: 2025 | B6: 1 | C6: 22 | D6: FG | E6: Outbound | F6: 34654 | G6: 11892.568 | H6: 67.571407 | I6: 29.526829 | J6: 351149.8 | K6: 2.9139208 | L6: 1575.1818 | M6: 512.85006 | N6: 10.133024 | O6: 28345.232 | P6: 10479.799 | Q6: 59.544313 | R6: 29.526829 | S6: 309435.23 | T6: 2.7047496 | U6: 1288.4196 | V6: 476.03592 | W6: 10.916659
A7: 2025 | B7: 1 | C7: 22 | D7: FG | E7: Total | F7: 65706 | G7: 22549 | H7: 128.11932 | I7: 29.526829 | J7: 665800.46 | K7: 2.9139208 | L7: 2986.6364 | M7: 512.85006 | N7: 10.133024 | O7: 56457.107 | P7: 20873.321 | Q7: 118.59842 | R7: 29.526829 | S7: 616322.98 | T7: 2.7047496 | U7: 2566.2321 | V7: 476.03592 | W7: 10.916659
A8: 2025 | B8: 1 | C8: 22 | D8: VAL | E8: Total | F8: 209420 | G8: 6034 | H8: 34.284091 | I8: 29.526829 | J8: 178164.88 | K8: 34.706662 | L8: 9519.0909 | M8: 6108.3726 | N8: 0.85075391 | O8: 219409 | P8: 6505.7103 | Q8: 36.964263 | R8: 29.526829 | S8: 192092.99 | T8: 33.725602 | U8: 9973.1364 | V8: 5935.706 | W8: 0.87550189
A9: 2025 | B9: 1 | C9: 22 | D9: Others | E9: Total | F9: 0 | G9: 1132 | H9: 6.4318182 | I9: 29.526829 | J9: 33424.37 | K9: 0 | L9: 0 | M9: 0 | N9: 0 | O9: 0 | P9: 2302.0206 | Q9: 13.079662 | R9: 29.526829 | S9: 67971.367 | T9: 0 | U9: 0 | V9: 0 | W9: 0
A10: 2025 | B10: 2 | C10: 20 | D10: R&P | E10: Inbound | F10: 11796 | G10: 2300.8996 | H10: 14.380623 | I10: 28.703985 | J10: 66044.988 | K10: 5.1266904 | L10: 589.8 | M10: 820.27046 | N10: 5.5989308 | O10: 11407 | P10: 1961.2977 | Q10: 12.258111 | R10: 28.703985 | S10: 56297.06 | T10: 5.8160471 | U10: 570.35 | V10: 930.56753 | W10: 4.9353082
A11: 2025 | B11: 2 | C11: 20 | D11: R&P | E11: Outbound | F11: 9813 | G11: 1914.1004 | H11: 11.963127 | I11: 28.703985 | J11: 54942.308 | K11: 5.1266904 | L11: 490.65 | M11: 820.27046 | N11: 5.5989308 | O11: 9229 | P11: 1586.8166 | Q11: 9.9176037 | R11: 28.703985 | S11: 45547.959 | T11: 5.8160471 | U11: 461.45 | V11: 930.56753 | W11: 4.9353082
A12: 2025 | B12: 2 | C12: 20 | D12: R&P | E12: Total | F12: 21609 | G12: 4215 | H12: 26.34375 | I12: 28.703985 | J12: 120987.3 | K12: 5.1266904 | L12: 1080.45 | M12: 820.27046 | N12: 5.5989308 | O12: 20636 | P12: 3548.1143 | Q12: 22.175715 | R12: 28.703985 | S12: 101845.02 | T12: 5.8160471 | U12: 1031.8 | V12: 930.56753 | W12: 4.9353082
A13: 2025 | B13: 2 | C13: 20 | D13: FG | E13: Inbound | F13: 25857 | G13: 8660.4453 | H13: 54.127783 | I13: 28.703985 | J13: 248589.29 | K13: 2.9856432 | L13: 1292.85 | M13: 477.70292 | N13: 9.6140036 | O13: 28111.875 | P13: 10393.522 | Q13: 64.959515 | R13: 28.703985 | S13: 298335.51 | T13: 2.7047496 | U13: 1405.5938 | V13: 432.75993 | W13: 10.612437
... A89: 2025 | B89: 11 | C89: 20 | D89: Others | E89: Total | F89: 0 | G89: 913.36667 | H89: 5.7085417 | I89: 30.922753 | J89: 28243.811 | K89: 0 | L89: 0 | M89: 0 | N89: 0 | O89: 0 | P89: 2299.7566 | Q89: 14.373479 | R89: 30.922753 | S89: 71114.805 | T89: 0 | U89: 0 | V89: 0 | W89: 0
